2025-04-25 04:32:16,114 ERROR scheduler Exception in Enqueue Events for Site erpnext.localhost
Traceback (most recent call last):
  File "/home/alevason/eval/env/lib/python3.12/site-packages/redis/connection.py", line 357, in connect
    sock = self.retry.call_with_retry(
           ^^^^^^^^^^^^^^^^^^^^^^^^^^^
  File "/home/alevason/eval/env/lib/python3.12/site-packages/redis/retry.py", line 62, in call_with_retry
    return do()
           ^^^^
  File "/home/alevason/eval/env/lib/python3.12/site-packages/redis/connection.py", line 358, in <lambda>
    lambda: self._connect(), lambda error: self.disconnect(error)
            ^^^^^^^^^^^^^^^
  File "/home/alevason/eval/env/lib/python3.12/site-packages/redis/connection.py", line 730, in _connect
    raise err
  File "/home/alevason/eval/env/lib/python3.12/site-packages/redis/connection.py", line 718, in _connect
    sock.connect(socket_address)
ConnectionRefusedError: [Errno 111] Connection refused

During handling of the above exception, another exception occurred:

Traceback (most recent call last):
  File "/home/alevason/eval/apps/frappe/frappe/utils/scheduler.py", line 120, in enqueue_events_for_site
    enqueue_events()
  File "/home/alevason/eval/apps/frappe/frappe/utils/scheduler.py", line 140, in enqueue_events
    if job_type.enqueue():
       ^^^^^^^^^^^^^^^^^^
  File "/home/alevason/eval/apps/frappe/frappe/core/doctype/scheduled_job_type/scheduled_job_type.py", line 71, in enqueue
    if not self.is_job_in_queue():
           ^^^^^^^^^^^^^^^^^^^^^^
  File "/home/alevason/eval/apps/frappe/frappe/core/doctype/scheduled_job_type/scheduled_job_type.py", line 93, in is_job_in_queue
    return is_job_enqueued(self.rq_job_id)
           ^^^^^^^^^^^^^^^^^^^^^^^^^^^^^^^
  File "/home/alevason/eval/apps/frappe/frappe/utils/background_jobs.py", line 654, in is_job_enqueued
    return get_job_status(job_id) in (JobStatus.QUEUED, JobStatus.STARTED)
           ^^^^^^^^^^^^^^^^^^^^^^
  File "/home/alevason/eval/apps/frappe/frappe/utils/background_jobs.py", line 659, in get_job_status
    if job := get_job(job_id):
              ^^^^^^^^^^^^^^^
  File "/home/alevason/eval/apps/frappe/frappe/utils/background_jobs.py", line 665, in get_job
    return Job.fetch(create_job_id(job_id), connection=get_redis_conn())
                                                       ^^^^^^^^^^^^^^^^
  File "/home/alevason/eval/env/lib/python3.12/site-packages/tenacity/__init__.py", line 289, in wrapped_f
    return self(f, *args, **kw)
           ^^^^^^^^^^^^^^^^^^^^
  File "/home/alevason/eval/env/lib/python3.12/site-packages/tenacity/__init__.py", line 379, in __call__
    do = self.iter(retry_state=retry_state)
         ^^^^^^^^^^^^^^^^^^^^^^^^^^^^^^^^^^
  File "/home/alevason/eval/env/lib/python3.12/site-packages/tenacity/__init__.py", line 325, in iter
    raise retry_exc.reraise()
          ^^^^^^^^^^^^^^^^^^^
  File "/home/alevason/eval/env/lib/python3.12/site-packages/tenacity/__init__.py", line 158, in reraise
    raise self.last_attempt.result()
          ^^^^^^^^^^^^^^^^^^^^^^^^^^
  File "/usr/lib/python3.12/concurrent/futures/_base.py", line 449, in result
    return self.__get_result()
           ^^^^^^^^^^^^^^^^^^^
  File "/usr/lib/python3.12/concurrent/futures/_base.py", line 401, in __get_result
    raise self._exception
  File "/home/alevason/eval/env/lib/python3.12/site-packages/tenacity/__init__.py", line 382, in __call__
    result = fn(*args, **kwargs)
             ^^^^^^^^^^^^^^^^^^^
  File "/home/alevason/eval/apps/frappe/frappe/utils/background_jobs.py", line 579, in get_redis_conn
    return get_redis_connection_without_auth()
           ^^^^^^^^^^^^^^^^^^^^^^^^^^^^^^^^^^^
  File "/home/alevason/eval/apps/frappe/frappe/utils/background_jobs.py", line 601, in get_redis_connection_without_auth
    _redis_queue_conn = RedisQueue.get_connection()
                        ^^^^^^^^^^^^^^^^^^^^^^^^^^^
  File "/home/alevason/eval/apps/frappe/frappe/utils/redis_queue.py", line 36, in get_connection
    conn.ping()
  File "/home/alevason/eval/env/lib/python3.12/site-packages/redis/commands/core.py", line 1212, in ping
    return self.execute_command("PING", **kwargs)
           ^^^^^^^^^^^^^^^^^^^^^^^^^^^^^^^^^^^^^^
  File "/home/alevason/eval/env/lib/python3.12/site-packages/redis/client.py", line 559, in execute_command
    return self._execute_command(*args, **options)
           ^^^^^^^^^^^^^^^^^^^^^^^^^^^^^^^^^^^^^^^
  File "/home/alevason/eval/env/lib/python3.12/site-packages/redis/client.py", line 565, in _execute_command
    conn = self.connection or pool.get_connection(command_name, **options)
                              ^^^^^^^^^^^^^^^^^^^^^^^^^^^^^^^^^^^^^^^^^^^^
  File "/home/alevason/eval/env/lib/python3.12/site-packages/redis/connection.py", line 1422, in get_connection
    connection.connect()
  File "/home/alevason/eval/env/lib/python3.12/site-packages/redis/connection.py", line 363, in connect
    raise ConnectionError(self._error_message(e))
redis.exceptions.ConnectionError: Error 111 connecting to 127.0.0.1:11000. Connection refused.
2025-04-25 04:36:14,181 ERROR scheduler Exception in Enqueue Events for Site erpnext.localhost
Traceback (most recent call last):
  File "/home/alevason/eval/env/lib/python3.12/site-packages/redis/connection.py", line 357, in connect
    sock = self.retry.call_with_retry(
           ^^^^^^^^^^^^^^^^^^^^^^^^^^^
  File "/home/alevason/eval/env/lib/python3.12/site-packages/redis/retry.py", line 62, in call_with_retry
    return do()
           ^^^^
  File "/home/alevason/eval/env/lib/python3.12/site-packages/redis/connection.py", line 358, in <lambda>
    lambda: self._connect(), lambda error: self.disconnect(error)
            ^^^^^^^^^^^^^^^
  File "/home/alevason/eval/env/lib/python3.12/site-packages/redis/connection.py", line 730, in _connect
    raise err
  File "/home/alevason/eval/env/lib/python3.12/site-packages/redis/connection.py", line 718, in _connect
    sock.connect(socket_address)
ConnectionRefusedError: [Errno 111] Connection refused

During handling of the above exception, another exception occurred:

Traceback (most recent call last):
  File "/home/alevason/eval/apps/frappe/frappe/utils/scheduler.py", line 120, in enqueue_events_for_site
    enqueue_events()
  File "/home/alevason/eval/apps/frappe/frappe/utils/scheduler.py", line 140, in enqueue_events
    if job_type.enqueue():
       ^^^^^^^^^^^^^^^^^^
  File "/home/alevason/eval/apps/frappe/frappe/core/doctype/scheduled_job_type/scheduled_job_type.py", line 71, in enqueue
    if not self.is_job_in_queue():
           ^^^^^^^^^^^^^^^^^^^^^^
  File "/home/alevason/eval/apps/frappe/frappe/core/doctype/scheduled_job_type/scheduled_job_type.py", line 93, in is_job_in_queue
    return is_job_enqueued(self.rq_job_id)
           ^^^^^^^^^^^^^^^^^^^^^^^^^^^^^^^
  File "/home/alevason/eval/apps/frappe/frappe/utils/background_jobs.py", line 654, in is_job_enqueued
    return get_job_status(job_id) in (JobStatus.QUEUED, JobStatus.STARTED)
           ^^^^^^^^^^^^^^^^^^^^^^
  File "/home/alevason/eval/apps/frappe/frappe/utils/background_jobs.py", line 659, in get_job_status
    if job := get_job(job_id):
              ^^^^^^^^^^^^^^^
  File "/home/alevason/eval/apps/frappe/frappe/utils/background_jobs.py", line 665, in get_job
    return Job.fetch(create_job_id(job_id), connection=get_redis_conn())
                                                       ^^^^^^^^^^^^^^^^
  File "/home/alevason/eval/env/lib/python3.12/site-packages/tenacity/__init__.py", line 289, in wrapped_f
    return self(f, *args, **kw)
           ^^^^^^^^^^^^^^^^^^^^
  File "/home/alevason/eval/env/lib/python3.12/site-packages/tenacity/__init__.py", line 379, in __call__
    do = self.iter(retry_state=retry_state)
         ^^^^^^^^^^^^^^^^^^^^^^^^^^^^^^^^^^
  File "/home/alevason/eval/env/lib/python3.12/site-packages/tenacity/__init__.py", line 325, in iter
    raise retry_exc.reraise()
          ^^^^^^^^^^^^^^^^^^^
  File "/home/alevason/eval/env/lib/python3.12/site-packages/tenacity/__init__.py", line 158, in reraise
    raise self.last_attempt.result()
          ^^^^^^^^^^^^^^^^^^^^^^^^^^
  File "/usr/lib/python3.12/concurrent/futures/_base.py", line 449, in result
    return self.__get_result()
           ^^^^^^^^^^^^^^^^^^^
  File "/usr/lib/python3.12/concurrent/futures/_base.py", line 401, in __get_result
    raise self._exception
  File "/home/alevason/eval/env/lib/python3.12/site-packages/tenacity/__init__.py", line 382, in __call__
    result = fn(*args, **kwargs)
             ^^^^^^^^^^^^^^^^^^^
  File "/home/alevason/eval/apps/frappe/frappe/utils/background_jobs.py", line 579, in get_redis_conn
    return get_redis_connection_without_auth()
           ^^^^^^^^^^^^^^^^^^^^^^^^^^^^^^^^^^^
  File "/home/alevason/eval/apps/frappe/frappe/utils/background_jobs.py", line 601, in get_redis_connection_without_auth
    _redis_queue_conn = RedisQueue.get_connection()
                        ^^^^^^^^^^^^^^^^^^^^^^^^^^^
  File "/home/alevason/eval/apps/frappe/frappe/utils/redis_queue.py", line 36, in get_connection
    conn.ping()
  File "/home/alevason/eval/env/lib/python3.12/site-packages/redis/commands/core.py", line 1212, in ping
    return self.execute_command("PING", **kwargs)
           ^^^^^^^^^^^^^^^^^^^^^^^^^^^^^^^^^^^^^^
  File "/home/alevason/eval/env/lib/python3.12/site-packages/redis/client.py", line 559, in execute_command
    return self._execute_command(*args, **options)
           ^^^^^^^^^^^^^^^^^^^^^^^^^^^^^^^^^^^^^^^
  File "/home/alevason/eval/env/lib/python3.12/site-packages/redis/client.py", line 565, in _execute_command
    conn = self.connection or pool.get_connection(command_name, **options)
                              ^^^^^^^^^^^^^^^^^^^^^^^^^^^^^^^^^^^^^^^^^^^^
  File "/home/alevason/eval/env/lib/python3.12/site-packages/redis/connection.py", line 1422, in get_connection
    connection.connect()
  File "/home/alevason/eval/env/lib/python3.12/site-packages/redis/connection.py", line 363, in connect
    raise ConnectionError(self._error_message(e))
redis.exceptions.ConnectionError: Error 111 connecting to 127.0.0.1:11000. Connection refused.
2025-04-25 04:40:14,190 ERROR scheduler Exception in Enqueue Events for Site erpnext.localhost
Traceback (most recent call last):
  File "/home/alevason/eval/env/lib/python3.12/site-packages/redis/connection.py", line 357, in connect
    sock = self.retry.call_with_retry(
           ^^^^^^^^^^^^^^^^^^^^^^^^^^^
  File "/home/alevason/eval/env/lib/python3.12/site-packages/redis/retry.py", line 62, in call_with_retry
    return do()
           ^^^^
  File "/home/alevason/eval/env/lib/python3.12/site-packages/redis/connection.py", line 358, in <lambda>
    lambda: self._connect(), lambda error: self.disconnect(error)
            ^^^^^^^^^^^^^^^
  File "/home/alevason/eval/env/lib/python3.12/site-packages/redis/connection.py", line 730, in _connect
    raise err
  File "/home/alevason/eval/env/lib/python3.12/site-packages/redis/connection.py", line 718, in _connect
    sock.connect(socket_address)
ConnectionRefusedError: [Errno 111] Connection refused

During handling of the above exception, another exception occurred:

Traceback (most recent call last):
  File "/home/alevason/eval/apps/frappe/frappe/utils/scheduler.py", line 120, in enqueue_events_for_site
    enqueue_events()
  File "/home/alevason/eval/apps/frappe/frappe/utils/scheduler.py", line 140, in enqueue_events
    if job_type.enqueue():
       ^^^^^^^^^^^^^^^^^^
  File "/home/alevason/eval/apps/frappe/frappe/core/doctype/scheduled_job_type/scheduled_job_type.py", line 71, in enqueue
    if not self.is_job_in_queue():
           ^^^^^^^^^^^^^^^^^^^^^^
  File "/home/alevason/eval/apps/frappe/frappe/core/doctype/scheduled_job_type/scheduled_job_type.py", line 93, in is_job_in_queue
    return is_job_enqueued(self.rq_job_id)
           ^^^^^^^^^^^^^^^^^^^^^^^^^^^^^^^
  File "/home/alevason/eval/apps/frappe/frappe/utils/background_jobs.py", line 654, in is_job_enqueued
    return get_job_status(job_id) in (JobStatus.QUEUED, JobStatus.STARTED)
           ^^^^^^^^^^^^^^^^^^^^^^
  File "/home/alevason/eval/apps/frappe/frappe/utils/background_jobs.py", line 659, in get_job_status
    if job := get_job(job_id):
              ^^^^^^^^^^^^^^^
  File "/home/alevason/eval/apps/frappe/frappe/utils/background_jobs.py", line 665, in get_job
    return Job.fetch(create_job_id(job_id), connection=get_redis_conn())
                                                       ^^^^^^^^^^^^^^^^
  File "/home/alevason/eval/env/lib/python3.12/site-packages/tenacity/__init__.py", line 289, in wrapped_f
    return self(f, *args, **kw)
           ^^^^^^^^^^^^^^^^^^^^
  File "/home/alevason/eval/env/lib/python3.12/site-packages/tenacity/__init__.py", line 379, in __call__
    do = self.iter(retry_state=retry_state)
         ^^^^^^^^^^^^^^^^^^^^^^^^^^^^^^^^^^
  File "/home/alevason/eval/env/lib/python3.12/site-packages/tenacity/__init__.py", line 325, in iter
    raise retry_exc.reraise()
          ^^^^^^^^^^^^^^^^^^^
  File "/home/alevason/eval/env/lib/python3.12/site-packages/tenacity/__init__.py", line 158, in reraise
    raise self.last_attempt.result()
          ^^^^^^^^^^^^^^^^^^^^^^^^^^
  File "/usr/lib/python3.12/concurrent/futures/_base.py", line 449, in result
    return self.__get_result()
           ^^^^^^^^^^^^^^^^^^^
  File "/usr/lib/python3.12/concurrent/futures/_base.py", line 401, in __get_result
    raise self._exception
  File "/home/alevason/eval/env/lib/python3.12/site-packages/tenacity/__init__.py", line 382, in __call__
    result = fn(*args, **kwargs)
             ^^^^^^^^^^^^^^^^^^^
  File "/home/alevason/eval/apps/frappe/frappe/utils/background_jobs.py", line 579, in get_redis_conn
    return get_redis_connection_without_auth()
           ^^^^^^^^^^^^^^^^^^^^^^^^^^^^^^^^^^^
  File "/home/alevason/eval/apps/frappe/frappe/utils/background_jobs.py", line 601, in get_redis_connection_without_auth
    _redis_queue_conn = RedisQueue.get_connection()
                        ^^^^^^^^^^^^^^^^^^^^^^^^^^^
  File "/home/alevason/eval/apps/frappe/frappe/utils/redis_queue.py", line 36, in get_connection
    conn.ping()
  File "/home/alevason/eval/env/lib/python3.12/site-packages/redis/commands/core.py", line 1212, in ping
    return self.execute_command("PING", **kwargs)
           ^^^^^^^^^^^^^^^^^^^^^^^^^^^^^^^^^^^^^^
  File "/home/alevason/eval/env/lib/python3.12/site-packages/redis/client.py", line 559, in execute_command
    return self._execute_command(*args, **options)
           ^^^^^^^^^^^^^^^^^^^^^^^^^^^^^^^^^^^^^^^
  File "/home/alevason/eval/env/lib/python3.12/site-packages/redis/client.py", line 565, in _execute_command
    conn = self.connection or pool.get_connection(command_name, **options)
                              ^^^^^^^^^^^^^^^^^^^^^^^^^^^^^^^^^^^^^^^^^^^^
  File "/home/alevason/eval/env/lib/python3.12/site-packages/redis/connection.py", line 1422, in get_connection
    connection.connect()
  File "/home/alevason/eval/env/lib/python3.12/site-packages/redis/connection.py", line 363, in connect
    raise ConnectionError(self._error_message(e))
redis.exceptions.ConnectionError: Error 111 connecting to 127.0.0.1:11000. Connection refused.
2025-04-25 04:44:14,329 ERROR scheduler Exception in Enqueue Events for Site erpnext.localhost
Traceback (most recent call last):
  File "/home/alevason/eval/env/lib/python3.12/site-packages/redis/connection.py", line 357, in connect
    sock = self.retry.call_with_retry(
           ^^^^^^^^^^^^^^^^^^^^^^^^^^^
  File "/home/alevason/eval/env/lib/python3.12/site-packages/redis/retry.py", line 62, in call_with_retry
    return do()
           ^^^^
  File "/home/alevason/eval/env/lib/python3.12/site-packages/redis/connection.py", line 358, in <lambda>
    lambda: self._connect(), lambda error: self.disconnect(error)
            ^^^^^^^^^^^^^^^
  File "/home/alevason/eval/env/lib/python3.12/site-packages/redis/connection.py", line 730, in _connect
    raise err
  File "/home/alevason/eval/env/lib/python3.12/site-packages/redis/connection.py", line 718, in _connect
    sock.connect(socket_address)
ConnectionRefusedError: [Errno 111] Connection refused

During handling of the above exception, another exception occurred:

Traceback (most recent call last):
  File "/home/alevason/eval/apps/frappe/frappe/utils/scheduler.py", line 120, in enqueue_events_for_site
    enqueue_events()
  File "/home/alevason/eval/apps/frappe/frappe/utils/scheduler.py", line 140, in enqueue_events
    if job_type.enqueue():
       ^^^^^^^^^^^^^^^^^^
  File "/home/alevason/eval/apps/frappe/frappe/core/doctype/scheduled_job_type/scheduled_job_type.py", line 71, in enqueue
    if not self.is_job_in_queue():
           ^^^^^^^^^^^^^^^^^^^^^^
  File "/home/alevason/eval/apps/frappe/frappe/core/doctype/scheduled_job_type/scheduled_job_type.py", line 93, in is_job_in_queue
    return is_job_enqueued(self.rq_job_id)
           ^^^^^^^^^^^^^^^^^^^^^^^^^^^^^^^
  File "/home/alevason/eval/apps/frappe/frappe/utils/background_jobs.py", line 654, in is_job_enqueued
    return get_job_status(job_id) in (JobStatus.QUEUED, JobStatus.STARTED)
           ^^^^^^^^^^^^^^^^^^^^^^
  File "/home/alevason/eval/apps/frappe/frappe/utils/background_jobs.py", line 659, in get_job_status
    if job := get_job(job_id):
              ^^^^^^^^^^^^^^^
  File "/home/alevason/eval/apps/frappe/frappe/utils/background_jobs.py", line 665, in get_job
    return Job.fetch(create_job_id(job_id), connection=get_redis_conn())
                                                       ^^^^^^^^^^^^^^^^
  File "/home/alevason/eval/env/lib/python3.12/site-packages/tenacity/__init__.py", line 289, in wrapped_f
    return self(f, *args, **kw)
           ^^^^^^^^^^^^^^^^^^^^
  File "/home/alevason/eval/env/lib/python3.12/site-packages/tenacity/__init__.py", line 379, in __call__
    do = self.iter(retry_state=retry_state)
         ^^^^^^^^^^^^^^^^^^^^^^^^^^^^^^^^^^
  File "/home/alevason/eval/env/lib/python3.12/site-packages/tenacity/__init__.py", line 325, in iter
    raise retry_exc.reraise()
          ^^^^^^^^^^^^^^^^^^^
  File "/home/alevason/eval/env/lib/python3.12/site-packages/tenacity/__init__.py", line 158, in reraise
    raise self.last_attempt.result()
          ^^^^^^^^^^^^^^^^^^^^^^^^^^
  File "/usr/lib/python3.12/concurrent/futures/_base.py", line 449, in result
    return self.__get_result()
           ^^^^^^^^^^^^^^^^^^^
  File "/usr/lib/python3.12/concurrent/futures/_base.py", line 401, in __get_result
    raise self._exception
  File "/home/alevason/eval/env/lib/python3.12/site-packages/tenacity/__init__.py", line 382, in __call__
    result = fn(*args, **kwargs)
             ^^^^^^^^^^^^^^^^^^^
  File "/home/alevason/eval/apps/frappe/frappe/utils/background_jobs.py", line 579, in get_redis_conn
    return get_redis_connection_without_auth()
           ^^^^^^^^^^^^^^^^^^^^^^^^^^^^^^^^^^^
  File "/home/alevason/eval/apps/frappe/frappe/utils/background_jobs.py", line 601, in get_redis_connection_without_auth
    _redis_queue_conn = RedisQueue.get_connection()
                        ^^^^^^^^^^^^^^^^^^^^^^^^^^^
  File "/home/alevason/eval/apps/frappe/frappe/utils/redis_queue.py", line 36, in get_connection
    conn.ping()
  File "/home/alevason/eval/env/lib/python3.12/site-packages/redis/commands/core.py", line 1212, in ping
    return self.execute_command("PING", **kwargs)
           ^^^^^^^^^^^^^^^^^^^^^^^^^^^^^^^^^^^^^^
  File "/home/alevason/eval/env/lib/python3.12/site-packages/redis/client.py", line 559, in execute_command
    return self._execute_command(*args, **options)
           ^^^^^^^^^^^^^^^^^^^^^^^^^^^^^^^^^^^^^^^
  File "/home/alevason/eval/env/lib/python3.12/site-packages/redis/client.py", line 565, in _execute_command
    conn = self.connection or pool.get_connection(command_name, **options)
                              ^^^^^^^^^^^^^^^^^^^^^^^^^^^^^^^^^^^^^^^^^^^^
  File "/home/alevason/eval/env/lib/python3.12/site-packages/redis/connection.py", line 1422, in get_connection
    connection.connect()
  File "/home/alevason/eval/env/lib/python3.12/site-packages/redis/connection.py", line 363, in connect
    raise ConnectionError(self._error_message(e))
redis.exceptions.ConnectionError: Error 111 connecting to 127.0.0.1:11000. Connection refused.
2025-04-25 04:48:14,385 ERROR scheduler Exception in Enqueue Events for Site erpnext.localhost
Traceback (most recent call last):
  File "/home/alevason/eval/env/lib/python3.12/site-packages/redis/connection.py", line 357, in connect
    sock = self.retry.call_with_retry(
           ^^^^^^^^^^^^^^^^^^^^^^^^^^^
  File "/home/alevason/eval/env/lib/python3.12/site-packages/redis/retry.py", line 62, in call_with_retry
    return do()
           ^^^^
  File "/home/alevason/eval/env/lib/python3.12/site-packages/redis/connection.py", line 358, in <lambda>
    lambda: self._connect(), lambda error: self.disconnect(error)
            ^^^^^^^^^^^^^^^
  File "/home/alevason/eval/env/lib/python3.12/site-packages/redis/connection.py", line 730, in _connect
    raise err
  File "/home/alevason/eval/env/lib/python3.12/site-packages/redis/connection.py", line 718, in _connect
    sock.connect(socket_address)
ConnectionRefusedError: [Errno 111] Connection refused

During handling of the above exception, another exception occurred:

Traceback (most recent call last):
  File "/home/alevason/eval/apps/frappe/frappe/utils/scheduler.py", line 120, in enqueue_events_for_site
    enqueue_events()
  File "/home/alevason/eval/apps/frappe/frappe/utils/scheduler.py", line 140, in enqueue_events
    if job_type.enqueue():
       ^^^^^^^^^^^^^^^^^^
  File "/home/alevason/eval/apps/frappe/frappe/core/doctype/scheduled_job_type/scheduled_job_type.py", line 71, in enqueue
    if not self.is_job_in_queue():
           ^^^^^^^^^^^^^^^^^^^^^^
  File "/home/alevason/eval/apps/frappe/frappe/core/doctype/scheduled_job_type/scheduled_job_type.py", line 93, in is_job_in_queue
    return is_job_enqueued(self.rq_job_id)
           ^^^^^^^^^^^^^^^^^^^^^^^^^^^^^^^
  File "/home/alevason/eval/apps/frappe/frappe/utils/background_jobs.py", line 654, in is_job_enqueued
    return get_job_status(job_id) in (JobStatus.QUEUED, JobStatus.STARTED)
           ^^^^^^^^^^^^^^^^^^^^^^
  File "/home/alevason/eval/apps/frappe/frappe/utils/background_jobs.py", line 659, in get_job_status
    if job := get_job(job_id):
              ^^^^^^^^^^^^^^^
  File "/home/alevason/eval/apps/frappe/frappe/utils/background_jobs.py", line 665, in get_job
    return Job.fetch(create_job_id(job_id), connection=get_redis_conn())
                                                       ^^^^^^^^^^^^^^^^
  File "/home/alevason/eval/env/lib/python3.12/site-packages/tenacity/__init__.py", line 289, in wrapped_f
    return self(f, *args, **kw)
           ^^^^^^^^^^^^^^^^^^^^
  File "/home/alevason/eval/env/lib/python3.12/site-packages/tenacity/__init__.py", line 379, in __call__
    do = self.iter(retry_state=retry_state)
         ^^^^^^^^^^^^^^^^^^^^^^^^^^^^^^^^^^
  File "/home/alevason/eval/env/lib/python3.12/site-packages/tenacity/__init__.py", line 325, in iter
    raise retry_exc.reraise()
          ^^^^^^^^^^^^^^^^^^^
  File "/home/alevason/eval/env/lib/python3.12/site-packages/tenacity/__init__.py", line 158, in reraise
    raise self.last_attempt.result()
          ^^^^^^^^^^^^^^^^^^^^^^^^^^
  File "/usr/lib/python3.12/concurrent/futures/_base.py", line 449, in result
    return self.__get_result()
           ^^^^^^^^^^^^^^^^^^^
  File "/usr/lib/python3.12/concurrent/futures/_base.py", line 401, in __get_result
    raise self._exception
  File "/home/alevason/eval/env/lib/python3.12/site-packages/tenacity/__init__.py", line 382, in __call__
    result = fn(*args, **kwargs)
             ^^^^^^^^^^^^^^^^^^^
  File "/home/alevason/eval/apps/frappe/frappe/utils/background_jobs.py", line 579, in get_redis_conn
    return get_redis_connection_without_auth()
           ^^^^^^^^^^^^^^^^^^^^^^^^^^^^^^^^^^^
  File "/home/alevason/eval/apps/frappe/frappe/utils/background_jobs.py", line 601, in get_redis_connection_without_auth
    _redis_queue_conn = RedisQueue.get_connection()
                        ^^^^^^^^^^^^^^^^^^^^^^^^^^^
  File "/home/alevason/eval/apps/frappe/frappe/utils/redis_queue.py", line 36, in get_connection
    conn.ping()
  File "/home/alevason/eval/env/lib/python3.12/site-packages/redis/commands/core.py", line 1212, in ping
    return self.execute_command("PING", **kwargs)
           ^^^^^^^^^^^^^^^^^^^^^^^^^^^^^^^^^^^^^^
  File "/home/alevason/eval/env/lib/python3.12/site-packages/redis/client.py", line 559, in execute_command
    return self._execute_command(*args, **options)
           ^^^^^^^^^^^^^^^^^^^^^^^^^^^^^^^^^^^^^^^
  File "/home/alevason/eval/env/lib/python3.12/site-packages/redis/client.py", line 565, in _execute_command
    conn = self.connection or pool.get_connection(command_name, **options)
                              ^^^^^^^^^^^^^^^^^^^^^^^^^^^^^^^^^^^^^^^^^^^^
  File "/home/alevason/eval/env/lib/python3.12/site-packages/redis/connection.py", line 1422, in get_connection
    connection.connect()
  File "/home/alevason/eval/env/lib/python3.12/site-packages/redis/connection.py", line 363, in connect
    raise ConnectionError(self._error_message(e))
redis.exceptions.ConnectionError: Error 111 connecting to 127.0.0.1:11000. Connection refused.
2025-04-25 04:52:14,749 ERROR scheduler Exception in Enqueue Events for Site erpnext.localhost
Traceback (most recent call last):
  File "/home/alevason/eval/env/lib/python3.12/site-packages/redis/connection.py", line 357, in connect
    sock = self.retry.call_with_retry(
           ^^^^^^^^^^^^^^^^^^^^^^^^^^^
  File "/home/alevason/eval/env/lib/python3.12/site-packages/redis/retry.py", line 62, in call_with_retry
    return do()
           ^^^^
  File "/home/alevason/eval/env/lib/python3.12/site-packages/redis/connection.py", line 358, in <lambda>
    lambda: self._connect(), lambda error: self.disconnect(error)
            ^^^^^^^^^^^^^^^
  File "/home/alevason/eval/env/lib/python3.12/site-packages/redis/connection.py", line 730, in _connect
    raise err
  File "/home/alevason/eval/env/lib/python3.12/site-packages/redis/connection.py", line 718, in _connect
    sock.connect(socket_address)
ConnectionRefusedError: [Errno 111] Connection refused

During handling of the above exception, another exception occurred:

Traceback (most recent call last):
  File "/home/alevason/eval/apps/frappe/frappe/utils/scheduler.py", line 120, in enqueue_events_for_site
    enqueue_events()
  File "/home/alevason/eval/apps/frappe/frappe/utils/scheduler.py", line 140, in enqueue_events
    if job_type.enqueue():
       ^^^^^^^^^^^^^^^^^^
  File "/home/alevason/eval/apps/frappe/frappe/core/doctype/scheduled_job_type/scheduled_job_type.py", line 71, in enqueue
    if not self.is_job_in_queue():
           ^^^^^^^^^^^^^^^^^^^^^^
  File "/home/alevason/eval/apps/frappe/frappe/core/doctype/scheduled_job_type/scheduled_job_type.py", line 93, in is_job_in_queue
    return is_job_enqueued(self.rq_job_id)
           ^^^^^^^^^^^^^^^^^^^^^^^^^^^^^^^
  File "/home/alevason/eval/apps/frappe/frappe/utils/background_jobs.py", line 654, in is_job_enqueued
    return get_job_status(job_id) in (JobStatus.QUEUED, JobStatus.STARTED)
           ^^^^^^^^^^^^^^^^^^^^^^
  File "/home/alevason/eval/apps/frappe/frappe/utils/background_jobs.py", line 659, in get_job_status
    if job := get_job(job_id):
              ^^^^^^^^^^^^^^^
  File "/home/alevason/eval/apps/frappe/frappe/utils/background_jobs.py", line 665, in get_job
    return Job.fetch(create_job_id(job_id), connection=get_redis_conn())
                                                       ^^^^^^^^^^^^^^^^
  File "/home/alevason/eval/env/lib/python3.12/site-packages/tenacity/__init__.py", line 289, in wrapped_f
    return self(f, *args, **kw)
           ^^^^^^^^^^^^^^^^^^^^
  File "/home/alevason/eval/env/lib/python3.12/site-packages/tenacity/__init__.py", line 379, in __call__
    do = self.iter(retry_state=retry_state)
         ^^^^^^^^^^^^^^^^^^^^^^^^^^^^^^^^^^
  File "/home/alevason/eval/env/lib/python3.12/site-packages/tenacity/__init__.py", line 325, in iter
    raise retry_exc.reraise()
          ^^^^^^^^^^^^^^^^^^^
  File "/home/alevason/eval/env/lib/python3.12/site-packages/tenacity/__init__.py", line 158, in reraise
    raise self.last_attempt.result()
          ^^^^^^^^^^^^^^^^^^^^^^^^^^
  File "/usr/lib/python3.12/concurrent/futures/_base.py", line 449, in result
    return self.__get_result()
           ^^^^^^^^^^^^^^^^^^^
  File "/usr/lib/python3.12/concurrent/futures/_base.py", line 401, in __get_result
    raise self._exception
  File "/home/alevason/eval/env/lib/python3.12/site-packages/tenacity/__init__.py", line 382, in __call__
    result = fn(*args, **kwargs)
             ^^^^^^^^^^^^^^^^^^^
  File "/home/alevason/eval/apps/frappe/frappe/utils/background_jobs.py", line 579, in get_redis_conn
    return get_redis_connection_without_auth()
           ^^^^^^^^^^^^^^^^^^^^^^^^^^^^^^^^^^^
  File "/home/alevason/eval/apps/frappe/frappe/utils/background_jobs.py", line 601, in get_redis_connection_without_auth
    _redis_queue_conn = RedisQueue.get_connection()
                        ^^^^^^^^^^^^^^^^^^^^^^^^^^^
  File "/home/alevason/eval/apps/frappe/frappe/utils/redis_queue.py", line 36, in get_connection
    conn.ping()
  File "/home/alevason/eval/env/lib/python3.12/site-packages/redis/commands/core.py", line 1212, in ping
    return self.execute_command("PING", **kwargs)
           ^^^^^^^^^^^^^^^^^^^^^^^^^^^^^^^^^^^^^^
  File "/home/alevason/eval/env/lib/python3.12/site-packages/redis/client.py", line 559, in execute_command
    return self._execute_command(*args, **options)
           ^^^^^^^^^^^^^^^^^^^^^^^^^^^^^^^^^^^^^^^
  File "/home/alevason/eval/env/lib/python3.12/site-packages/redis/client.py", line 565, in _execute_command
    conn = self.connection or pool.get_connection(command_name, **options)
                              ^^^^^^^^^^^^^^^^^^^^^^^^^^^^^^^^^^^^^^^^^^^^
  File "/home/alevason/eval/env/lib/python3.12/site-packages/redis/connection.py", line 1422, in get_connection
    connection.connect()
  File "/home/alevason/eval/env/lib/python3.12/site-packages/redis/connection.py", line 363, in connect
    raise ConnectionError(self._error_message(e))
redis.exceptions.ConnectionError: Error 111 connecting to 127.0.0.1:11000. Connection refused.
2025-04-25 04:56:14,533 ERROR scheduler Exception in Enqueue Events for Site erpnext.localhost
Traceback (most recent call last):
  File "/home/alevason/eval/env/lib/python3.12/site-packages/redis/connection.py", line 357, in connect
    sock = self.retry.call_with_retry(
           ^^^^^^^^^^^^^^^^^^^^^^^^^^^
  File "/home/alevason/eval/env/lib/python3.12/site-packages/redis/retry.py", line 62, in call_with_retry
    return do()
           ^^^^
  File "/home/alevason/eval/env/lib/python3.12/site-packages/redis/connection.py", line 358, in <lambda>
    lambda: self._connect(), lambda error: self.disconnect(error)
            ^^^^^^^^^^^^^^^
  File "/home/alevason/eval/env/lib/python3.12/site-packages/redis/connection.py", line 730, in _connect
    raise err
  File "/home/alevason/eval/env/lib/python3.12/site-packages/redis/connection.py", line 718, in _connect
    sock.connect(socket_address)
ConnectionRefusedError: [Errno 111] Connection refused

During handling of the above exception, another exception occurred:

Traceback (most recent call last):
  File "/home/alevason/eval/apps/frappe/frappe/utils/scheduler.py", line 120, in enqueue_events_for_site
    enqueue_events()
  File "/home/alevason/eval/apps/frappe/frappe/utils/scheduler.py", line 140, in enqueue_events
    if job_type.enqueue():
       ^^^^^^^^^^^^^^^^^^
  File "/home/alevason/eval/apps/frappe/frappe/core/doctype/scheduled_job_type/scheduled_job_type.py", line 71, in enqueue
    if not self.is_job_in_queue():
           ^^^^^^^^^^^^^^^^^^^^^^
  File "/home/alevason/eval/apps/frappe/frappe/core/doctype/scheduled_job_type/scheduled_job_type.py", line 93, in is_job_in_queue
    return is_job_enqueued(self.rq_job_id)
           ^^^^^^^^^^^^^^^^^^^^^^^^^^^^^^^
  File "/home/alevason/eval/apps/frappe/frappe/utils/background_jobs.py", line 654, in is_job_enqueued
    return get_job_status(job_id) in (JobStatus.QUEUED, JobStatus.STARTED)
           ^^^^^^^^^^^^^^^^^^^^^^
  File "/home/alevason/eval/apps/frappe/frappe/utils/background_jobs.py", line 659, in get_job_status
    if job := get_job(job_id):
              ^^^^^^^^^^^^^^^
  File "/home/alevason/eval/apps/frappe/frappe/utils/background_jobs.py", line 665, in get_job
    return Job.fetch(create_job_id(job_id), connection=get_redis_conn())
                                                       ^^^^^^^^^^^^^^^^
  File "/home/alevason/eval/env/lib/python3.12/site-packages/tenacity/__init__.py", line 289, in wrapped_f
    return self(f, *args, **kw)
           ^^^^^^^^^^^^^^^^^^^^
  File "/home/alevason/eval/env/lib/python3.12/site-packages/tenacity/__init__.py", line 379, in __call__
    do = self.iter(retry_state=retry_state)
         ^^^^^^^^^^^^^^^^^^^^^^^^^^^^^^^^^^
  File "/home/alevason/eval/env/lib/python3.12/site-packages/tenacity/__init__.py", line 325, in iter
    raise retry_exc.reraise()
          ^^^^^^^^^^^^^^^^^^^
  File "/home/alevason/eval/env/lib/python3.12/site-packages/tenacity/__init__.py", line 158, in reraise
    raise self.last_attempt.result()
          ^^^^^^^^^^^^^^^^^^^^^^^^^^
  File "/usr/lib/python3.12/concurrent/futures/_base.py", line 449, in result
    return self.__get_result()
           ^^^^^^^^^^^^^^^^^^^
  File "/usr/lib/python3.12/concurrent/futures/_base.py", line 401, in __get_result
    raise self._exception
  File "/home/alevason/eval/env/lib/python3.12/site-packages/tenacity/__init__.py", line 382, in __call__
    result = fn(*args, **kwargs)
             ^^^^^^^^^^^^^^^^^^^
  File "/home/alevason/eval/apps/frappe/frappe/utils/background_jobs.py", line 579, in get_redis_conn
    return get_redis_connection_without_auth()
           ^^^^^^^^^^^^^^^^^^^^^^^^^^^^^^^^^^^
  File "/home/alevason/eval/apps/frappe/frappe/utils/background_jobs.py", line 601, in get_redis_connection_without_auth
    _redis_queue_conn = RedisQueue.get_connection()
                        ^^^^^^^^^^^^^^^^^^^^^^^^^^^
  File "/home/alevason/eval/apps/frappe/frappe/utils/redis_queue.py", line 36, in get_connection
    conn.ping()
  File "/home/alevason/eval/env/lib/python3.12/site-packages/redis/commands/core.py", line 1212, in ping
    return self.execute_command("PING", **kwargs)
           ^^^^^^^^^^^^^^^^^^^^^^^^^^^^^^^^^^^^^^
  File "/home/alevason/eval/env/lib/python3.12/site-packages/redis/client.py", line 559, in execute_command
    return self._execute_command(*args, **options)
           ^^^^^^^^^^^^^^^^^^^^^^^^^^^^^^^^^^^^^^^
  File "/home/alevason/eval/env/lib/python3.12/site-packages/redis/client.py", line 565, in _execute_command
    conn = self.connection or pool.get_connection(command_name, **options)
                              ^^^^^^^^^^^^^^^^^^^^^^^^^^^^^^^^^^^^^^^^^^^^
  File "/home/alevason/eval/env/lib/python3.12/site-packages/redis/connection.py", line 1422, in get_connection
    connection.connect()
  File "/home/alevason/eval/env/lib/python3.12/site-packages/redis/connection.py", line 363, in connect
    raise ConnectionError(self._error_message(e))
redis.exceptions.ConnectionError: Error 111 connecting to 127.0.0.1:11000. Connection refused.
2025-04-25 05:00:10,353 ERROR scheduler Exception in Enqueue Events for Site erpnext.localhost
Traceback (most recent call last):
  File "/home/alevason/eval/env/lib/python3.12/site-packages/redis/connection.py", line 357, in connect
    sock = self.retry.call_with_retry(
           ^^^^^^^^^^^^^^^^^^^^^^^^^^^
  File "/home/alevason/eval/env/lib/python3.12/site-packages/redis/retry.py", line 62, in call_with_retry
    return do()
           ^^^^
  File "/home/alevason/eval/env/lib/python3.12/site-packages/redis/connection.py", line 358, in <lambda>
    lambda: self._connect(), lambda error: self.disconnect(error)
            ^^^^^^^^^^^^^^^
  File "/home/alevason/eval/env/lib/python3.12/site-packages/redis/connection.py", line 730, in _connect
    raise err
  File "/home/alevason/eval/env/lib/python3.12/site-packages/redis/connection.py", line 718, in _connect
    sock.connect(socket_address)
ConnectionRefusedError: [Errno 111] Connection refused

During handling of the above exception, another exception occurred:

Traceback (most recent call last):
  File "/home/alevason/eval/apps/frappe/frappe/utils/scheduler.py", line 120, in enqueue_events_for_site
    enqueue_events()
  File "/home/alevason/eval/apps/frappe/frappe/utils/scheduler.py", line 140, in enqueue_events
    if job_type.enqueue():
       ^^^^^^^^^^^^^^^^^^
  File "/home/alevason/eval/apps/frappe/frappe/core/doctype/scheduled_job_type/scheduled_job_type.py", line 71, in enqueue
    if not self.is_job_in_queue():
           ^^^^^^^^^^^^^^^^^^^^^^
  File "/home/alevason/eval/apps/frappe/frappe/core/doctype/scheduled_job_type/scheduled_job_type.py", line 93, in is_job_in_queue
    return is_job_enqueued(self.rq_job_id)
           ^^^^^^^^^^^^^^^^^^^^^^^^^^^^^^^
  File "/home/alevason/eval/apps/frappe/frappe/utils/background_jobs.py", line 654, in is_job_enqueued
    return get_job_status(job_id) in (JobStatus.QUEUED, JobStatus.STARTED)
           ^^^^^^^^^^^^^^^^^^^^^^
  File "/home/alevason/eval/apps/frappe/frappe/utils/background_jobs.py", line 659, in get_job_status
    if job := get_job(job_id):
              ^^^^^^^^^^^^^^^
  File "/home/alevason/eval/apps/frappe/frappe/utils/background_jobs.py", line 665, in get_job
    return Job.fetch(create_job_id(job_id), connection=get_redis_conn())
                                                       ^^^^^^^^^^^^^^^^
  File "/home/alevason/eval/env/lib/python3.12/site-packages/tenacity/__init__.py", line 289, in wrapped_f
    return self(f, *args, **kw)
           ^^^^^^^^^^^^^^^^^^^^
  File "/home/alevason/eval/env/lib/python3.12/site-packages/tenacity/__init__.py", line 379, in __call__
    do = self.iter(retry_state=retry_state)
         ^^^^^^^^^^^^^^^^^^^^^^^^^^^^^^^^^^
  File "/home/alevason/eval/env/lib/python3.12/site-packages/tenacity/__init__.py", line 325, in iter
    raise retry_exc.reraise()
          ^^^^^^^^^^^^^^^^^^^
  File "/home/alevason/eval/env/lib/python3.12/site-packages/tenacity/__init__.py", line 158, in reraise
    raise self.last_attempt.result()
          ^^^^^^^^^^^^^^^^^^^^^^^^^^
  File "/usr/lib/python3.12/concurrent/futures/_base.py", line 449, in result
    return self.__get_result()
           ^^^^^^^^^^^^^^^^^^^
  File "/usr/lib/python3.12/concurrent/futures/_base.py", line 401, in __get_result
    raise self._exception
  File "/home/alevason/eval/env/lib/python3.12/site-packages/tenacity/__init__.py", line 382, in __call__
    result = fn(*args, **kwargs)
             ^^^^^^^^^^^^^^^^^^^
  File "/home/alevason/eval/apps/frappe/frappe/utils/background_jobs.py", line 579, in get_redis_conn
    return get_redis_connection_without_auth()
           ^^^^^^^^^^^^^^^^^^^^^^^^^^^^^^^^^^^
  File "/home/alevason/eval/apps/frappe/frappe/utils/background_jobs.py", line 601, in get_redis_connection_without_auth
    _redis_queue_conn = RedisQueue.get_connection()
                        ^^^^^^^^^^^^^^^^^^^^^^^^^^^
  File "/home/alevason/eval/apps/frappe/frappe/utils/redis_queue.py", line 36, in get_connection
    conn.ping()
  File "/home/alevason/eval/env/lib/python3.12/site-packages/redis/commands/core.py", line 1212, in ping
    return self.execute_command("PING", **kwargs)
           ^^^^^^^^^^^^^^^^^^^^^^^^^^^^^^^^^^^^^^
  File "/home/alevason/eval/env/lib/python3.12/site-packages/redis/client.py", line 559, in execute_command
    return self._execute_command(*args, **options)
           ^^^^^^^^^^^^^^^^^^^^^^^^^^^^^^^^^^^^^^^
  File "/home/alevason/eval/env/lib/python3.12/site-packages/redis/client.py", line 565, in _execute_command
    conn = self.connection or pool.get_connection(command_name, **options)
                              ^^^^^^^^^^^^^^^^^^^^^^^^^^^^^^^^^^^^^^^^^^^^
  File "/home/alevason/eval/env/lib/python3.12/site-packages/redis/connection.py", line 1422, in get_connection
    connection.connect()
  File "/home/alevason/eval/env/lib/python3.12/site-packages/redis/connection.py", line 363, in connect
    raise ConnectionError(self._error_message(e))
redis.exceptions.ConnectionError: Error 111 connecting to 127.0.0.1:11000. Connection refused.
2025-04-25 05:04:11,718 ERROR scheduler Exception in Enqueue Events for Site erpnext.localhost
Traceback (most recent call last):
  File "/home/alevason/eval/env/lib/python3.12/site-packages/redis/connection.py", line 357, in connect
    sock = self.retry.call_with_retry(
           ^^^^^^^^^^^^^^^^^^^^^^^^^^^
  File "/home/alevason/eval/env/lib/python3.12/site-packages/redis/retry.py", line 62, in call_with_retry
    return do()
           ^^^^
  File "/home/alevason/eval/env/lib/python3.12/site-packages/redis/connection.py", line 358, in <lambda>
    lambda: self._connect(), lambda error: self.disconnect(error)
            ^^^^^^^^^^^^^^^
  File "/home/alevason/eval/env/lib/python3.12/site-packages/redis/connection.py", line 730, in _connect
    raise err
  File "/home/alevason/eval/env/lib/python3.12/site-packages/redis/connection.py", line 718, in _connect
    sock.connect(socket_address)
ConnectionRefusedError: [Errno 111] Connection refused

During handling of the above exception, another exception occurred:

Traceback (most recent call last):
  File "/home/alevason/eval/apps/frappe/frappe/utils/scheduler.py", line 120, in enqueue_events_for_site
    enqueue_events()
  File "/home/alevason/eval/apps/frappe/frappe/utils/scheduler.py", line 140, in enqueue_events
    if job_type.enqueue():
       ^^^^^^^^^^^^^^^^^^
  File "/home/alevason/eval/apps/frappe/frappe/core/doctype/scheduled_job_type/scheduled_job_type.py", line 71, in enqueue
    if not self.is_job_in_queue():
           ^^^^^^^^^^^^^^^^^^^^^^
  File "/home/alevason/eval/apps/frappe/frappe/core/doctype/scheduled_job_type/scheduled_job_type.py", line 93, in is_job_in_queue
    return is_job_enqueued(self.rq_job_id)
           ^^^^^^^^^^^^^^^^^^^^^^^^^^^^^^^
  File "/home/alevason/eval/apps/frappe/frappe/utils/background_jobs.py", line 654, in is_job_enqueued
    return get_job_status(job_id) in (JobStatus.QUEUED, JobStatus.STARTED)
           ^^^^^^^^^^^^^^^^^^^^^^
  File "/home/alevason/eval/apps/frappe/frappe/utils/background_jobs.py", line 659, in get_job_status
    if job := get_job(job_id):
              ^^^^^^^^^^^^^^^
  File "/home/alevason/eval/apps/frappe/frappe/utils/background_jobs.py", line 665, in get_job
    return Job.fetch(create_job_id(job_id), connection=get_redis_conn())
                                                       ^^^^^^^^^^^^^^^^
  File "/home/alevason/eval/env/lib/python3.12/site-packages/tenacity/__init__.py", line 289, in wrapped_f
    return self(f, *args, **kw)
           ^^^^^^^^^^^^^^^^^^^^
  File "/home/alevason/eval/env/lib/python3.12/site-packages/tenacity/__init__.py", line 379, in __call__
    do = self.iter(retry_state=retry_state)
         ^^^^^^^^^^^^^^^^^^^^^^^^^^^^^^^^^^
  File "/home/alevason/eval/env/lib/python3.12/site-packages/tenacity/__init__.py", line 325, in iter
    raise retry_exc.reraise()
          ^^^^^^^^^^^^^^^^^^^
  File "/home/alevason/eval/env/lib/python3.12/site-packages/tenacity/__init__.py", line 158, in reraise
    raise self.last_attempt.result()
          ^^^^^^^^^^^^^^^^^^^^^^^^^^
  File "/usr/lib/python3.12/concurrent/futures/_base.py", line 449, in result
    return self.__get_result()
           ^^^^^^^^^^^^^^^^^^^
  File "/usr/lib/python3.12/concurrent/futures/_base.py", line 401, in __get_result
    raise self._exception
  File "/home/alevason/eval/env/lib/python3.12/site-packages/tenacity/__init__.py", line 382, in __call__
    result = fn(*args, **kwargs)
             ^^^^^^^^^^^^^^^^^^^
  File "/home/alevason/eval/apps/frappe/frappe/utils/background_jobs.py", line 579, in get_redis_conn
    return get_redis_connection_without_auth()
           ^^^^^^^^^^^^^^^^^^^^^^^^^^^^^^^^^^^
  File "/home/alevason/eval/apps/frappe/frappe/utils/background_jobs.py", line 601, in get_redis_connection_without_auth
    _redis_queue_conn = RedisQueue.get_connection()
                        ^^^^^^^^^^^^^^^^^^^^^^^^^^^
  File "/home/alevason/eval/apps/frappe/frappe/utils/redis_queue.py", line 36, in get_connection
    conn.ping()
  File "/home/alevason/eval/env/lib/python3.12/site-packages/redis/commands/core.py", line 1212, in ping
    return self.execute_command("PING", **kwargs)
           ^^^^^^^^^^^^^^^^^^^^^^^^^^^^^^^^^^^^^^
  File "/home/alevason/eval/env/lib/python3.12/site-packages/redis/client.py", line 559, in execute_command
    return self._execute_command(*args, **options)
           ^^^^^^^^^^^^^^^^^^^^^^^^^^^^^^^^^^^^^^^
  File "/home/alevason/eval/env/lib/python3.12/site-packages/redis/client.py", line 565, in _execute_command
    conn = self.connection or pool.get_connection(command_name, **options)
                              ^^^^^^^^^^^^^^^^^^^^^^^^^^^^^^^^^^^^^^^^^^^^
  File "/home/alevason/eval/env/lib/python3.12/site-packages/redis/connection.py", line 1422, in get_connection
    connection.connect()
  File "/home/alevason/eval/env/lib/python3.12/site-packages/redis/connection.py", line 363, in connect
    raise ConnectionError(self._error_message(e))
redis.exceptions.ConnectionError: Error 111 connecting to 127.0.0.1:11000. Connection refused.
2025-04-25 05:08:11,912 ERROR scheduler Exception in Enqueue Events for Site erpnext.localhost
Traceback (most recent call last):
  File "/home/alevason/eval/env/lib/python3.12/site-packages/redis/connection.py", line 357, in connect
    sock = self.retry.call_with_retry(
           ^^^^^^^^^^^^^^^^^^^^^^^^^^^
  File "/home/alevason/eval/env/lib/python3.12/site-packages/redis/retry.py", line 62, in call_with_retry
    return do()
           ^^^^
  File "/home/alevason/eval/env/lib/python3.12/site-packages/redis/connection.py", line 358, in <lambda>
    lambda: self._connect(), lambda error: self.disconnect(error)
            ^^^^^^^^^^^^^^^
  File "/home/alevason/eval/env/lib/python3.12/site-packages/redis/connection.py", line 730, in _connect
    raise err
  File "/home/alevason/eval/env/lib/python3.12/site-packages/redis/connection.py", line 718, in _connect
    sock.connect(socket_address)
ConnectionRefusedError: [Errno 111] Connection refused

During handling of the above exception, another exception occurred:

Traceback (most recent call last):
  File "/home/alevason/eval/apps/frappe/frappe/utils/scheduler.py", line 120, in enqueue_events_for_site
    enqueue_events()
  File "/home/alevason/eval/apps/frappe/frappe/utils/scheduler.py", line 140, in enqueue_events
    if job_type.enqueue():
       ^^^^^^^^^^^^^^^^^^
  File "/home/alevason/eval/apps/frappe/frappe/core/doctype/scheduled_job_type/scheduled_job_type.py", line 71, in enqueue
    if not self.is_job_in_queue():
           ^^^^^^^^^^^^^^^^^^^^^^
  File "/home/alevason/eval/apps/frappe/frappe/core/doctype/scheduled_job_type/scheduled_job_type.py", line 93, in is_job_in_queue
    return is_job_enqueued(self.rq_job_id)
           ^^^^^^^^^^^^^^^^^^^^^^^^^^^^^^^
  File "/home/alevason/eval/apps/frappe/frappe/utils/background_jobs.py", line 654, in is_job_enqueued
    return get_job_status(job_id) in (JobStatus.QUEUED, JobStatus.STARTED)
           ^^^^^^^^^^^^^^^^^^^^^^
  File "/home/alevason/eval/apps/frappe/frappe/utils/background_jobs.py", line 659, in get_job_status
    if job := get_job(job_id):
              ^^^^^^^^^^^^^^^
  File "/home/alevason/eval/apps/frappe/frappe/utils/background_jobs.py", line 665, in get_job
    return Job.fetch(create_job_id(job_id), connection=get_redis_conn())
                                                       ^^^^^^^^^^^^^^^^
  File "/home/alevason/eval/env/lib/python3.12/site-packages/tenacity/__init__.py", line 289, in wrapped_f
    return self(f, *args, **kw)
           ^^^^^^^^^^^^^^^^^^^^
  File "/home/alevason/eval/env/lib/python3.12/site-packages/tenacity/__init__.py", line 379, in __call__
    do = self.iter(retry_state=retry_state)
         ^^^^^^^^^^^^^^^^^^^^^^^^^^^^^^^^^^
  File "/home/alevason/eval/env/lib/python3.12/site-packages/tenacity/__init__.py", line 325, in iter
    raise retry_exc.reraise()
          ^^^^^^^^^^^^^^^^^^^
  File "/home/alevason/eval/env/lib/python3.12/site-packages/tenacity/__init__.py", line 158, in reraise
    raise self.last_attempt.result()
          ^^^^^^^^^^^^^^^^^^^^^^^^^^
  File "/usr/lib/python3.12/concurrent/futures/_base.py", line 449, in result
    return self.__get_result()
           ^^^^^^^^^^^^^^^^^^^
  File "/usr/lib/python3.12/concurrent/futures/_base.py", line 401, in __get_result
    raise self._exception
  File "/home/alevason/eval/env/lib/python3.12/site-packages/tenacity/__init__.py", line 382, in __call__
    result = fn(*args, **kwargs)
             ^^^^^^^^^^^^^^^^^^^
  File "/home/alevason/eval/apps/frappe/frappe/utils/background_jobs.py", line 579, in get_redis_conn
    return get_redis_connection_without_auth()
           ^^^^^^^^^^^^^^^^^^^^^^^^^^^^^^^^^^^
  File "/home/alevason/eval/apps/frappe/frappe/utils/background_jobs.py", line 601, in get_redis_connection_without_auth
    _redis_queue_conn = RedisQueue.get_connection()
                        ^^^^^^^^^^^^^^^^^^^^^^^^^^^
  File "/home/alevason/eval/apps/frappe/frappe/utils/redis_queue.py", line 36, in get_connection
    conn.ping()
  File "/home/alevason/eval/env/lib/python3.12/site-packages/redis/commands/core.py", line 1212, in ping
    return self.execute_command("PING", **kwargs)
           ^^^^^^^^^^^^^^^^^^^^^^^^^^^^^^^^^^^^^^
  File "/home/alevason/eval/env/lib/python3.12/site-packages/redis/client.py", line 559, in execute_command
    return self._execute_command(*args, **options)
           ^^^^^^^^^^^^^^^^^^^^^^^^^^^^^^^^^^^^^^^
  File "/home/alevason/eval/env/lib/python3.12/site-packages/redis/client.py", line 565, in _execute_command
    conn = self.connection or pool.get_connection(command_name, **options)
                              ^^^^^^^^^^^^^^^^^^^^^^^^^^^^^^^^^^^^^^^^^^^^
  File "/home/alevason/eval/env/lib/python3.12/site-packages/redis/connection.py", line 1422, in get_connection
    connection.connect()
  File "/home/alevason/eval/env/lib/python3.12/site-packages/redis/connection.py", line 363, in connect
    raise ConnectionError(self._error_message(e))
redis.exceptions.ConnectionError: Error 111 connecting to 127.0.0.1:11000. Connection refused.
2025-04-25 05:12:13,643 ERROR scheduler Exception in Enqueue Events for Site erpnext.localhost
Traceback (most recent call last):
  File "/home/alevason/eval/env/lib/python3.12/site-packages/redis/connection.py", line 357, in connect
    sock = self.retry.call_with_retry(
           ^^^^^^^^^^^^^^^^^^^^^^^^^^^
  File "/home/alevason/eval/env/lib/python3.12/site-packages/redis/retry.py", line 62, in call_with_retry
    return do()
           ^^^^
  File "/home/alevason/eval/env/lib/python3.12/site-packages/redis/connection.py", line 358, in <lambda>
    lambda: self._connect(), lambda error: self.disconnect(error)
            ^^^^^^^^^^^^^^^
  File "/home/alevason/eval/env/lib/python3.12/site-packages/redis/connection.py", line 730, in _connect
    raise err
  File "/home/alevason/eval/env/lib/python3.12/site-packages/redis/connection.py", line 718, in _connect
    sock.connect(socket_address)
ConnectionRefusedError: [Errno 111] Connection refused

During handling of the above exception, another exception occurred:

Traceback (most recent call last):
  File "/home/alevason/eval/apps/frappe/frappe/utils/scheduler.py", line 120, in enqueue_events_for_site
    enqueue_events()
  File "/home/alevason/eval/apps/frappe/frappe/utils/scheduler.py", line 140, in enqueue_events
    if job_type.enqueue():
       ^^^^^^^^^^^^^^^^^^
  File "/home/alevason/eval/apps/frappe/frappe/core/doctype/scheduled_job_type/scheduled_job_type.py", line 71, in enqueue
    if not self.is_job_in_queue():
           ^^^^^^^^^^^^^^^^^^^^^^
  File "/home/alevason/eval/apps/frappe/frappe/core/doctype/scheduled_job_type/scheduled_job_type.py", line 93, in is_job_in_queue
    return is_job_enqueued(self.rq_job_id)
           ^^^^^^^^^^^^^^^^^^^^^^^^^^^^^^^
  File "/home/alevason/eval/apps/frappe/frappe/utils/background_jobs.py", line 654, in is_job_enqueued
    return get_job_status(job_id) in (JobStatus.QUEUED, JobStatus.STARTED)
           ^^^^^^^^^^^^^^^^^^^^^^
  File "/home/alevason/eval/apps/frappe/frappe/utils/background_jobs.py", line 659, in get_job_status
    if job := get_job(job_id):
              ^^^^^^^^^^^^^^^
  File "/home/alevason/eval/apps/frappe/frappe/utils/background_jobs.py", line 665, in get_job
    return Job.fetch(create_job_id(job_id), connection=get_redis_conn())
                                                       ^^^^^^^^^^^^^^^^
  File "/home/alevason/eval/env/lib/python3.12/site-packages/tenacity/__init__.py", line 289, in wrapped_f
    return self(f, *args, **kw)
           ^^^^^^^^^^^^^^^^^^^^
  File "/home/alevason/eval/env/lib/python3.12/site-packages/tenacity/__init__.py", line 379, in __call__
    do = self.iter(retry_state=retry_state)
         ^^^^^^^^^^^^^^^^^^^^^^^^^^^^^^^^^^
  File "/home/alevason/eval/env/lib/python3.12/site-packages/tenacity/__init__.py", line 325, in iter
    raise retry_exc.reraise()
          ^^^^^^^^^^^^^^^^^^^
  File "/home/alevason/eval/env/lib/python3.12/site-packages/tenacity/__init__.py", line 158, in reraise
    raise self.last_attempt.result()
          ^^^^^^^^^^^^^^^^^^^^^^^^^^
  File "/usr/lib/python3.12/concurrent/futures/_base.py", line 449, in result
    return self.__get_result()
           ^^^^^^^^^^^^^^^^^^^
  File "/usr/lib/python3.12/concurrent/futures/_base.py", line 401, in __get_result
    raise self._exception
  File "/home/alevason/eval/env/lib/python3.12/site-packages/tenacity/__init__.py", line 382, in __call__
    result = fn(*args, **kwargs)
             ^^^^^^^^^^^^^^^^^^^
  File "/home/alevason/eval/apps/frappe/frappe/utils/background_jobs.py", line 579, in get_redis_conn
    return get_redis_connection_without_auth()
           ^^^^^^^^^^^^^^^^^^^^^^^^^^^^^^^^^^^
  File "/home/alevason/eval/apps/frappe/frappe/utils/background_jobs.py", line 601, in get_redis_connection_without_auth
    _redis_queue_conn = RedisQueue.get_connection()
                        ^^^^^^^^^^^^^^^^^^^^^^^^^^^
  File "/home/alevason/eval/apps/frappe/frappe/utils/redis_queue.py", line 36, in get_connection
    conn.ping()
  File "/home/alevason/eval/env/lib/python3.12/site-packages/redis/commands/core.py", line 1212, in ping
    return self.execute_command("PING", **kwargs)
           ^^^^^^^^^^^^^^^^^^^^^^^^^^^^^^^^^^^^^^
  File "/home/alevason/eval/env/lib/python3.12/site-packages/redis/client.py", line 559, in execute_command
    return self._execute_command(*args, **options)
           ^^^^^^^^^^^^^^^^^^^^^^^^^^^^^^^^^^^^^^^
  File "/home/alevason/eval/env/lib/python3.12/site-packages/redis/client.py", line 565, in _execute_command
    conn = self.connection or pool.get_connection(command_name, **options)
                              ^^^^^^^^^^^^^^^^^^^^^^^^^^^^^^^^^^^^^^^^^^^^
  File "/home/alevason/eval/env/lib/python3.12/site-packages/redis/connection.py", line 1422, in get_connection
    connection.connect()
  File "/home/alevason/eval/env/lib/python3.12/site-packages/redis/connection.py", line 363, in connect
    raise ConnectionError(self._error_message(e))
redis.exceptions.ConnectionError: Error 111 connecting to 127.0.0.1:11000. Connection refused.
2025-04-25 05:16:13,321 ERROR scheduler Exception in Enqueue Events for Site erpnext.localhost
Traceback (most recent call last):
  File "/home/alevason/eval/env/lib/python3.12/site-packages/redis/connection.py", line 357, in connect
    sock = self.retry.call_with_retry(
           ^^^^^^^^^^^^^^^^^^^^^^^^^^^
  File "/home/alevason/eval/env/lib/python3.12/site-packages/redis/retry.py", line 62, in call_with_retry
    return do()
           ^^^^
  File "/home/alevason/eval/env/lib/python3.12/site-packages/redis/connection.py", line 358, in <lambda>
    lambda: self._connect(), lambda error: self.disconnect(error)
            ^^^^^^^^^^^^^^^
  File "/home/alevason/eval/env/lib/python3.12/site-packages/redis/connection.py", line 730, in _connect
    raise err
  File "/home/alevason/eval/env/lib/python3.12/site-packages/redis/connection.py", line 718, in _connect
    sock.connect(socket_address)
ConnectionRefusedError: [Errno 111] Connection refused

During handling of the above exception, another exception occurred:

Traceback (most recent call last):
  File "/home/alevason/eval/apps/frappe/frappe/utils/scheduler.py", line 120, in enqueue_events_for_site
    enqueue_events()
  File "/home/alevason/eval/apps/frappe/frappe/utils/scheduler.py", line 140, in enqueue_events
    if job_type.enqueue():
       ^^^^^^^^^^^^^^^^^^
  File "/home/alevason/eval/apps/frappe/frappe/core/doctype/scheduled_job_type/scheduled_job_type.py", line 71, in enqueue
    if not self.is_job_in_queue():
           ^^^^^^^^^^^^^^^^^^^^^^
  File "/home/alevason/eval/apps/frappe/frappe/core/doctype/scheduled_job_type/scheduled_job_type.py", line 93, in is_job_in_queue
    return is_job_enqueued(self.rq_job_id)
           ^^^^^^^^^^^^^^^^^^^^^^^^^^^^^^^
  File "/home/alevason/eval/apps/frappe/frappe/utils/background_jobs.py", line 654, in is_job_enqueued
    return get_job_status(job_id) in (JobStatus.QUEUED, JobStatus.STARTED)
           ^^^^^^^^^^^^^^^^^^^^^^
  File "/home/alevason/eval/apps/frappe/frappe/utils/background_jobs.py", line 659, in get_job_status
    if job := get_job(job_id):
              ^^^^^^^^^^^^^^^
  File "/home/alevason/eval/apps/frappe/frappe/utils/background_jobs.py", line 665, in get_job
    return Job.fetch(create_job_id(job_id), connection=get_redis_conn())
                                                       ^^^^^^^^^^^^^^^^
  File "/home/alevason/eval/env/lib/python3.12/site-packages/tenacity/__init__.py", line 289, in wrapped_f
    return self(f, *args, **kw)
           ^^^^^^^^^^^^^^^^^^^^
  File "/home/alevason/eval/env/lib/python3.12/site-packages/tenacity/__init__.py", line 379, in __call__
    do = self.iter(retry_state=retry_state)
         ^^^^^^^^^^^^^^^^^^^^^^^^^^^^^^^^^^
  File "/home/alevason/eval/env/lib/python3.12/site-packages/tenacity/__init__.py", line 325, in iter
    raise retry_exc.reraise()
          ^^^^^^^^^^^^^^^^^^^
  File "/home/alevason/eval/env/lib/python3.12/site-packages/tenacity/__init__.py", line 158, in reraise
    raise self.last_attempt.result()
          ^^^^^^^^^^^^^^^^^^^^^^^^^^
  File "/usr/lib/python3.12/concurrent/futures/_base.py", line 449, in result
    return self.__get_result()
           ^^^^^^^^^^^^^^^^^^^
  File "/usr/lib/python3.12/concurrent/futures/_base.py", line 401, in __get_result
    raise self._exception
  File "/home/alevason/eval/env/lib/python3.12/site-packages/tenacity/__init__.py", line 382, in __call__
    result = fn(*args, **kwargs)
             ^^^^^^^^^^^^^^^^^^^
  File "/home/alevason/eval/apps/frappe/frappe/utils/background_jobs.py", line 579, in get_redis_conn
    return get_redis_connection_without_auth()
           ^^^^^^^^^^^^^^^^^^^^^^^^^^^^^^^^^^^
  File "/home/alevason/eval/apps/frappe/frappe/utils/background_jobs.py", line 601, in get_redis_connection_without_auth
    _redis_queue_conn = RedisQueue.get_connection()
                        ^^^^^^^^^^^^^^^^^^^^^^^^^^^
  File "/home/alevason/eval/apps/frappe/frappe/utils/redis_queue.py", line 36, in get_connection
    conn.ping()
  File "/home/alevason/eval/env/lib/python3.12/site-packages/redis/commands/core.py", line 1212, in ping
    return self.execute_command("PING", **kwargs)
           ^^^^^^^^^^^^^^^^^^^^^^^^^^^^^^^^^^^^^^
  File "/home/alevason/eval/env/lib/python3.12/site-packages/redis/client.py", line 559, in execute_command
    return self._execute_command(*args, **options)
           ^^^^^^^^^^^^^^^^^^^^^^^^^^^^^^^^^^^^^^^
  File "/home/alevason/eval/env/lib/python3.12/site-packages/redis/client.py", line 565, in _execute_command
    conn = self.connection or pool.get_connection(command_name, **options)
                              ^^^^^^^^^^^^^^^^^^^^^^^^^^^^^^^^^^^^^^^^^^^^
  File "/home/alevason/eval/env/lib/python3.12/site-packages/redis/connection.py", line 1422, in get_connection
    connection.connect()
  File "/home/alevason/eval/env/lib/python3.12/site-packages/redis/connection.py", line 363, in connect
    raise ConnectionError(self._error_message(e))
redis.exceptions.ConnectionError: Error 111 connecting to 127.0.0.1:11000. Connection refused.
2025-04-25 05:20:12,801 ERROR scheduler Exception in Enqueue Events for Site erpnext.localhost
Traceback (most recent call last):
  File "/home/alevason/eval/env/lib/python3.12/site-packages/redis/connection.py", line 357, in connect
    sock = self.retry.call_with_retry(
           ^^^^^^^^^^^^^^^^^^^^^^^^^^^
  File "/home/alevason/eval/env/lib/python3.12/site-packages/redis/retry.py", line 62, in call_with_retry
    return do()
           ^^^^
  File "/home/alevason/eval/env/lib/python3.12/site-packages/redis/connection.py", line 358, in <lambda>
    lambda: self._connect(), lambda error: self.disconnect(error)
            ^^^^^^^^^^^^^^^
  File "/home/alevason/eval/env/lib/python3.12/site-packages/redis/connection.py", line 730, in _connect
    raise err
  File "/home/alevason/eval/env/lib/python3.12/site-packages/redis/connection.py", line 718, in _connect
    sock.connect(socket_address)
ConnectionRefusedError: [Errno 111] Connection refused

During handling of the above exception, another exception occurred:

Traceback (most recent call last):
  File "/home/alevason/eval/apps/frappe/frappe/utils/scheduler.py", line 120, in enqueue_events_for_site
    enqueue_events()
  File "/home/alevason/eval/apps/frappe/frappe/utils/scheduler.py", line 140, in enqueue_events
    if job_type.enqueue():
       ^^^^^^^^^^^^^^^^^^
  File "/home/alevason/eval/apps/frappe/frappe/core/doctype/scheduled_job_type/scheduled_job_type.py", line 71, in enqueue
    if not self.is_job_in_queue():
           ^^^^^^^^^^^^^^^^^^^^^^
  File "/home/alevason/eval/apps/frappe/frappe/core/doctype/scheduled_job_type/scheduled_job_type.py", line 93, in is_job_in_queue
    return is_job_enqueued(self.rq_job_id)
           ^^^^^^^^^^^^^^^^^^^^^^^^^^^^^^^
  File "/home/alevason/eval/apps/frappe/frappe/utils/background_jobs.py", line 654, in is_job_enqueued
    return get_job_status(job_id) in (JobStatus.QUEUED, JobStatus.STARTED)
           ^^^^^^^^^^^^^^^^^^^^^^
  File "/home/alevason/eval/apps/frappe/frappe/utils/background_jobs.py", line 659, in get_job_status
    if job := get_job(job_id):
              ^^^^^^^^^^^^^^^
  File "/home/alevason/eval/apps/frappe/frappe/utils/background_jobs.py", line 665, in get_job
    return Job.fetch(create_job_id(job_id), connection=get_redis_conn())
                                                       ^^^^^^^^^^^^^^^^
  File "/home/alevason/eval/env/lib/python3.12/site-packages/tenacity/__init__.py", line 289, in wrapped_f
    return self(f, *args, **kw)
           ^^^^^^^^^^^^^^^^^^^^
  File "/home/alevason/eval/env/lib/python3.12/site-packages/tenacity/__init__.py", line 379, in __call__
    do = self.iter(retry_state=retry_state)
         ^^^^^^^^^^^^^^^^^^^^^^^^^^^^^^^^^^
  File "/home/alevason/eval/env/lib/python3.12/site-packages/tenacity/__init__.py", line 325, in iter
    raise retry_exc.reraise()
          ^^^^^^^^^^^^^^^^^^^
  File "/home/alevason/eval/env/lib/python3.12/site-packages/tenacity/__init__.py", line 158, in reraise
    raise self.last_attempt.result()
          ^^^^^^^^^^^^^^^^^^^^^^^^^^
  File "/usr/lib/python3.12/concurrent/futures/_base.py", line 449, in result
    return self.__get_result()
           ^^^^^^^^^^^^^^^^^^^
  File "/usr/lib/python3.12/concurrent/futures/_base.py", line 401, in __get_result
    raise self._exception
  File "/home/alevason/eval/env/lib/python3.12/site-packages/tenacity/__init__.py", line 382, in __call__
    result = fn(*args, **kwargs)
             ^^^^^^^^^^^^^^^^^^^
  File "/home/alevason/eval/apps/frappe/frappe/utils/background_jobs.py", line 579, in get_redis_conn
    return get_redis_connection_without_auth()
           ^^^^^^^^^^^^^^^^^^^^^^^^^^^^^^^^^^^
  File "/home/alevason/eval/apps/frappe/frappe/utils/background_jobs.py", line 601, in get_redis_connection_without_auth
    _redis_queue_conn = RedisQueue.get_connection()
                        ^^^^^^^^^^^^^^^^^^^^^^^^^^^
  File "/home/alevason/eval/apps/frappe/frappe/utils/redis_queue.py", line 36, in get_connection
    conn.ping()
  File "/home/alevason/eval/env/lib/python3.12/site-packages/redis/commands/core.py", line 1212, in ping
    return self.execute_command("PING", **kwargs)
           ^^^^^^^^^^^^^^^^^^^^^^^^^^^^^^^^^^^^^^
  File "/home/alevason/eval/env/lib/python3.12/site-packages/redis/client.py", line 559, in execute_command
    return self._execute_command(*args, **options)
           ^^^^^^^^^^^^^^^^^^^^^^^^^^^^^^^^^^^^^^^
  File "/home/alevason/eval/env/lib/python3.12/site-packages/redis/client.py", line 565, in _execute_command
    conn = self.connection or pool.get_connection(command_name, **options)
                              ^^^^^^^^^^^^^^^^^^^^^^^^^^^^^^^^^^^^^^^^^^^^
  File "/home/alevason/eval/env/lib/python3.12/site-packages/redis/connection.py", line 1422, in get_connection
    connection.connect()
  File "/home/alevason/eval/env/lib/python3.12/site-packages/redis/connection.py", line 363, in connect
    raise ConnectionError(self._error_message(e))
redis.exceptions.ConnectionError: Error 111 connecting to 127.0.0.1:11000. Connection refused.
2025-04-25 05:24:14,549 ERROR scheduler Exception in Enqueue Events for Site erpnext.localhost
Traceback (most recent call last):
  File "/home/alevason/eval/env/lib/python3.12/site-packages/redis/connection.py", line 357, in connect
    sock = self.retry.call_with_retry(
           ^^^^^^^^^^^^^^^^^^^^^^^^^^^
  File "/home/alevason/eval/env/lib/python3.12/site-packages/redis/retry.py", line 62, in call_with_retry
    return do()
           ^^^^
  File "/home/alevason/eval/env/lib/python3.12/site-packages/redis/connection.py", line 358, in <lambda>
    lambda: self._connect(), lambda error: self.disconnect(error)
            ^^^^^^^^^^^^^^^
  File "/home/alevason/eval/env/lib/python3.12/site-packages/redis/connection.py", line 730, in _connect
    raise err
  File "/home/alevason/eval/env/lib/python3.12/site-packages/redis/connection.py", line 718, in _connect
    sock.connect(socket_address)
ConnectionRefusedError: [Errno 111] Connection refused

During handling of the above exception, another exception occurred:

Traceback (most recent call last):
  File "/home/alevason/eval/apps/frappe/frappe/utils/scheduler.py", line 120, in enqueue_events_for_site
    enqueue_events()
  File "/home/alevason/eval/apps/frappe/frappe/utils/scheduler.py", line 140, in enqueue_events
    if job_type.enqueue():
       ^^^^^^^^^^^^^^^^^^
  File "/home/alevason/eval/apps/frappe/frappe/core/doctype/scheduled_job_type/scheduled_job_type.py", line 71, in enqueue
    if not self.is_job_in_queue():
           ^^^^^^^^^^^^^^^^^^^^^^
  File "/home/alevason/eval/apps/frappe/frappe/core/doctype/scheduled_job_type/scheduled_job_type.py", line 93, in is_job_in_queue
    return is_job_enqueued(self.rq_job_id)
           ^^^^^^^^^^^^^^^^^^^^^^^^^^^^^^^
  File "/home/alevason/eval/apps/frappe/frappe/utils/background_jobs.py", line 654, in is_job_enqueued
    return get_job_status(job_id) in (JobStatus.QUEUED, JobStatus.STARTED)
           ^^^^^^^^^^^^^^^^^^^^^^
  File "/home/alevason/eval/apps/frappe/frappe/utils/background_jobs.py", line 659, in get_job_status
    if job := get_job(job_id):
              ^^^^^^^^^^^^^^^
  File "/home/alevason/eval/apps/frappe/frappe/utils/background_jobs.py", line 665, in get_job
    return Job.fetch(create_job_id(job_id), connection=get_redis_conn())
                                                       ^^^^^^^^^^^^^^^^
  File "/home/alevason/eval/env/lib/python3.12/site-packages/tenacity/__init__.py", line 289, in wrapped_f
    return self(f, *args, **kw)
           ^^^^^^^^^^^^^^^^^^^^
  File "/home/alevason/eval/env/lib/python3.12/site-packages/tenacity/__init__.py", line 379, in __call__
    do = self.iter(retry_state=retry_state)
         ^^^^^^^^^^^^^^^^^^^^^^^^^^^^^^^^^^
  File "/home/alevason/eval/env/lib/python3.12/site-packages/tenacity/__init__.py", line 325, in iter
    raise retry_exc.reraise()
          ^^^^^^^^^^^^^^^^^^^
  File "/home/alevason/eval/env/lib/python3.12/site-packages/tenacity/__init__.py", line 158, in reraise
    raise self.last_attempt.result()
          ^^^^^^^^^^^^^^^^^^^^^^^^^^
  File "/usr/lib/python3.12/concurrent/futures/_base.py", line 449, in result
    return self.__get_result()
           ^^^^^^^^^^^^^^^^^^^
  File "/usr/lib/python3.12/concurrent/futures/_base.py", line 401, in __get_result
    raise self._exception
  File "/home/alevason/eval/env/lib/python3.12/site-packages/tenacity/__init__.py", line 382, in __call__
    result = fn(*args, **kwargs)
             ^^^^^^^^^^^^^^^^^^^
  File "/home/alevason/eval/apps/frappe/frappe/utils/background_jobs.py", line 579, in get_redis_conn
    return get_redis_connection_without_auth()
           ^^^^^^^^^^^^^^^^^^^^^^^^^^^^^^^^^^^
  File "/home/alevason/eval/apps/frappe/frappe/utils/background_jobs.py", line 601, in get_redis_connection_without_auth
    _redis_queue_conn = RedisQueue.get_connection()
                        ^^^^^^^^^^^^^^^^^^^^^^^^^^^
  File "/home/alevason/eval/apps/frappe/frappe/utils/redis_queue.py", line 36, in get_connection
    conn.ping()
  File "/home/alevason/eval/env/lib/python3.12/site-packages/redis/commands/core.py", line 1212, in ping
    return self.execute_command("PING", **kwargs)
           ^^^^^^^^^^^^^^^^^^^^^^^^^^^^^^^^^^^^^^
  File "/home/alevason/eval/env/lib/python3.12/site-packages/redis/client.py", line 559, in execute_command
    return self._execute_command(*args, **options)
           ^^^^^^^^^^^^^^^^^^^^^^^^^^^^^^^^^^^^^^^
  File "/home/alevason/eval/env/lib/python3.12/site-packages/redis/client.py", line 565, in _execute_command
    conn = self.connection or pool.get_connection(command_name, **options)
                              ^^^^^^^^^^^^^^^^^^^^^^^^^^^^^^^^^^^^^^^^^^^^
  File "/home/alevason/eval/env/lib/python3.12/site-packages/redis/connection.py", line 1422, in get_connection
    connection.connect()
  File "/home/alevason/eval/env/lib/python3.12/site-packages/redis/connection.py", line 363, in connect
    raise ConnectionError(self._error_message(e))
redis.exceptions.ConnectionError: Error 111 connecting to 127.0.0.1:11000. Connection refused.
2025-04-25 05:28:13,498 ERROR scheduler Exception in Enqueue Events for Site erpnext.localhost
Traceback (most recent call last):
  File "/home/alevason/eval/env/lib/python3.12/site-packages/redis/connection.py", line 357, in connect
    sock = self.retry.call_with_retry(
           ^^^^^^^^^^^^^^^^^^^^^^^^^^^
  File "/home/alevason/eval/env/lib/python3.12/site-packages/redis/retry.py", line 62, in call_with_retry
    return do()
           ^^^^
  File "/home/alevason/eval/env/lib/python3.12/site-packages/redis/connection.py", line 358, in <lambda>
    lambda: self._connect(), lambda error: self.disconnect(error)
            ^^^^^^^^^^^^^^^
  File "/home/alevason/eval/env/lib/python3.12/site-packages/redis/connection.py", line 730, in _connect
    raise err
  File "/home/alevason/eval/env/lib/python3.12/site-packages/redis/connection.py", line 718, in _connect
    sock.connect(socket_address)
ConnectionRefusedError: [Errno 111] Connection refused

During handling of the above exception, another exception occurred:

Traceback (most recent call last):
  File "/home/alevason/eval/apps/frappe/frappe/utils/scheduler.py", line 120, in enqueue_events_for_site
    enqueue_events()
  File "/home/alevason/eval/apps/frappe/frappe/utils/scheduler.py", line 140, in enqueue_events
    if job_type.enqueue():
       ^^^^^^^^^^^^^^^^^^
  File "/home/alevason/eval/apps/frappe/frappe/core/doctype/scheduled_job_type/scheduled_job_type.py", line 71, in enqueue
    if not self.is_job_in_queue():
           ^^^^^^^^^^^^^^^^^^^^^^
  File "/home/alevason/eval/apps/frappe/frappe/core/doctype/scheduled_job_type/scheduled_job_type.py", line 93, in is_job_in_queue
    return is_job_enqueued(self.rq_job_id)
           ^^^^^^^^^^^^^^^^^^^^^^^^^^^^^^^
  File "/home/alevason/eval/apps/frappe/frappe/utils/background_jobs.py", line 654, in is_job_enqueued
    return get_job_status(job_id) in (JobStatus.QUEUED, JobStatus.STARTED)
           ^^^^^^^^^^^^^^^^^^^^^^
  File "/home/alevason/eval/apps/frappe/frappe/utils/background_jobs.py", line 659, in get_job_status
    if job := get_job(job_id):
              ^^^^^^^^^^^^^^^
  File "/home/alevason/eval/apps/frappe/frappe/utils/background_jobs.py", line 665, in get_job
    return Job.fetch(create_job_id(job_id), connection=get_redis_conn())
                                                       ^^^^^^^^^^^^^^^^
  File "/home/alevason/eval/env/lib/python3.12/site-packages/tenacity/__init__.py", line 289, in wrapped_f
    return self(f, *args, **kw)
           ^^^^^^^^^^^^^^^^^^^^
  File "/home/alevason/eval/env/lib/python3.12/site-packages/tenacity/__init__.py", line 379, in __call__
    do = self.iter(retry_state=retry_state)
         ^^^^^^^^^^^^^^^^^^^^^^^^^^^^^^^^^^
  File "/home/alevason/eval/env/lib/python3.12/site-packages/tenacity/__init__.py", line 325, in iter
    raise retry_exc.reraise()
          ^^^^^^^^^^^^^^^^^^^
  File "/home/alevason/eval/env/lib/python3.12/site-packages/tenacity/__init__.py", line 158, in reraise
    raise self.last_attempt.result()
          ^^^^^^^^^^^^^^^^^^^^^^^^^^
  File "/usr/lib/python3.12/concurrent/futures/_base.py", line 449, in result
    return self.__get_result()
           ^^^^^^^^^^^^^^^^^^^
  File "/usr/lib/python3.12/concurrent/futures/_base.py", line 401, in __get_result
    raise self._exception
  File "/home/alevason/eval/env/lib/python3.12/site-packages/tenacity/__init__.py", line 382, in __call__
    result = fn(*args, **kwargs)
             ^^^^^^^^^^^^^^^^^^^
  File "/home/alevason/eval/apps/frappe/frappe/utils/background_jobs.py", line 579, in get_redis_conn
    return get_redis_connection_without_auth()
           ^^^^^^^^^^^^^^^^^^^^^^^^^^^^^^^^^^^
  File "/home/alevason/eval/apps/frappe/frappe/utils/background_jobs.py", line 601, in get_redis_connection_without_auth
    _redis_queue_conn = RedisQueue.get_connection()
                        ^^^^^^^^^^^^^^^^^^^^^^^^^^^
  File "/home/alevason/eval/apps/frappe/frappe/utils/redis_queue.py", line 36, in get_connection
    conn.ping()
  File "/home/alevason/eval/env/lib/python3.12/site-packages/redis/commands/core.py", line 1212, in ping
    return self.execute_command("PING", **kwargs)
           ^^^^^^^^^^^^^^^^^^^^^^^^^^^^^^^^^^^^^^
  File "/home/alevason/eval/env/lib/python3.12/site-packages/redis/client.py", line 559, in execute_command
    return self._execute_command(*args, **options)
           ^^^^^^^^^^^^^^^^^^^^^^^^^^^^^^^^^^^^^^^
  File "/home/alevason/eval/env/lib/python3.12/site-packages/redis/client.py", line 565, in _execute_command
    conn = self.connection or pool.get_connection(command_name, **options)
                              ^^^^^^^^^^^^^^^^^^^^^^^^^^^^^^^^^^^^^^^^^^^^
  File "/home/alevason/eval/env/lib/python3.12/site-packages/redis/connection.py", line 1422, in get_connection
    connection.connect()
  File "/home/alevason/eval/env/lib/python3.12/site-packages/redis/connection.py", line 363, in connect
    raise ConnectionError(self._error_message(e))
redis.exceptions.ConnectionError: Error 111 connecting to 127.0.0.1:11000. Connection refused.
